<mujoco model="blue_full">
    <compiler angle="radian" />
    <size njmax="500" nconmax="100" />
    <asset>
        <mesh name="arm_base_link_v1" file="arm_base_link_v1.STL" />
        <mesh name="roll_link_v1" file="roll_link_v1.STL" />
        <mesh name="lift_link_v1" file="lift_link_v1.STL" />
        <mesh name="hand_base_link" file="hand_base_link.STL" />
        <mesh name="finger_limb_link" file="finger_limb_link.STL" />
        <mesh name="finger_tip_link" file="finger_tip_link.STL" />
        <mesh name="camera_link" file="camera_link.STL" />
    </asset>
    <worldbody>
        <body name="base_link" pos="0 0 0">
            <inertial pos="-0.0340721 -5.82248e-06 -0.701353" quat="0.999916 3.15548e-05 -0.0129229 -1.90294e-05" mass="16.2842" diaginertia="2.15017 1.86083 0.792594" />
            <geom size="0.5 0.375 0.0005" pos="0 0 -0.965" type="box" rgba="0.792157 0.819608 0.933333 1" />
            <body name="left_base_link" pos="-0.01409 0.11289 0" quat="-0.0778325 0.246839 0.290463 0.921219">
                <inertial pos="0.0560024 0.000189446 0.0201836" quat="-0.000530006 0.707989 0.00204572 0.70622" mass="0.284612" diaginertia="0.00239707 0.00197713 0.000716923" />
                <geom type="mesh" rgba="0.792157 0.819608 0.933333 1" mesh="arm_base_link_v1" />
                <body name="left_shoulder_roll_link" pos="0 0 0.087371" quat="-3.67321e-06 1 0 0">
                    <inertial pos="0.00526386 2.70692e-05 -0.0641638" quat="0.999876 0.0133095 -0.00835638 -0.000644765" mass="1.88492" diaginertia="0.00615005 0.00509851 0.00418291" />
                    <joint name="left_base_roll_joint" pos="0 0 0" axis="0 0 1" limited="true" range="-2.3412 3.3999" />
                    <geom type="mesh" rgba="1 1 1 1" mesh="roll_link_v1" />
                    <body name="left_shoulder_lift_link" pos="-0.01143 0 -0.18056" quat="-2.59734e-06 2.59735e-06 -0.707108 0.707105">
                        <inertial pos="-5.00836e-06 0.000232928 -1.77451e-05" mass="0.58967" diaginertia="0.00116314 0.000985221 0.000891661" />
                        <joint name="left_shoulder_lift_joint" pos="0 0 0" axis="0 0 1" limited="true" range="-2.2944 0" />
                        <geom type="mesh" rgba="0.116747 0.862745 1 1" mesh="lift_link_v1" />
                        <body name="left_elbow_roll_link" pos="0 0.070147 -6.25e-05" quat="0.499124 0.499126 0.500872 -0.500874">
                            <inertial pos="0.00526386 2.70692e-05 -0.0641638" quat="0.999876 0.0133095 -0.00835638 -0.000644765" mass="1.88492" diaginertia="0.00615005 0.00509851 0.00418291" />
                            <joint name="left_shoulder_roll_joint" pos="0 0 0" axis="0 0 1" limited="true" range="-2.6761 2.6761" />
                            <geom type="mesh" rgba="1 1 1 1" mesh="roll_link_v1" />
                            <body name="left_elbow_lift_link" pos="-0.01143 0 -0.18056" quat="-2.59734e-06 2.59735e-06 -0.707108 0.707105">
                                <inertial pos="-5.00836e-06 0.000232928 -1.77451e-05" mass="0.58967" diaginertia="0.00116314 0.000985221 0.000891661" />
                                <joint name="left_elbow_lift_joint" pos="0 0 0" axis="0 0 1" limited="true" range="-2.2944 0" />
                                <geom type="mesh" rgba="0.116747 0.862745 1 1" mesh="lift_link_v1" />
                                <body name="left_wrist_roll_link" pos="0 0.070147 -6.25e-05" quat="-0.499128 -0.499122 0.500876 -0.500871">
                                    <inertial pos="0.00526386 2.70692e-05 -0.0641638" quat="0.999876 0.0133095 -0.00835638 -0.000644765" mass="1.6251" diaginertia="0.00615005 0.00509851 0.00418291" />
                                    <joint name="left_elbow_roll_joint" pos="0 0 0" axis="0 0 1" limited="true" range="-2.6761 2.6761" />
                                    <geom type="mesh" rgba="1 1 1 1" mesh="roll_link_v1" />
                                    <body name="left_wrist_lift_link" pos="-0.01143 0 -0.18056" quat="-2.59734e-06 2.59735e-06 -0.707108 0.707105">
                                        <inertial pos="-5.00836e-06 0.000232928 -1.77451e-05" mass="0.44906" diaginertia="0.00116314 0.000985221 0.000891661" />
                                        <joint name="left_wrist_lift_joint" pos="0 0 0" axis="0 0 1" limited="true" range="-2.2944 0" />
                                        <geom type="mesh" rgba="0.116747 0.862745 1 1" mesh="lift_link_v1" />
                                        <body name="left_end_roll_link" pos="0 0.070147 -6.25e-05" quat="-2.59734e-06 2.59735e-06 0.707108 -0.707105">
                                            <inertial pos="0.00526386 2.70692e-05 -0.0641638" quat="0.99991 0.000246685 0.0133803 0.00035395" mass="0.65711" diaginertia="0.00578835 0.00530224 0.0034223" />
                                            <joint name="left_wrist_roll_joint" pos="0 0 0" axis="0 0 1" limited="true" range="-2.6761 2.6761" />
                                            <geom type="mesh" rgba="1 1 1 1" mesh="hand_base_link" />
                                            <body name="left_gripper_link" pos="0 0 -0.1" quat="0.535369 0.498747 0.498747 -0.464631">
                                                <inertial pos="-7.00549e-05 2.51272e-05 -0.0523671" quat="1 5.54202e-05 -0.000544908 -0.000762021" mass="0.00471098" diaginertia="0.000916889 0.000877269 0.000293332" />
                                                <joint name="left_gripper_joint" pos="0 0 0" axis="0 0 1" limited="true" range="0 1.05" />
                                            </body>
                                            <body name="left_r_finger_link" pos="0 0.030703 -0.071979" quat="0.631851 -0.317432 -0.631853 0.317432">
                                                <inertial pos="0.000467332 0.0122666 1.16453e-07" quat="0.705809 0.705807 -0.042877 -0.0427953" mass="0.0384621" diaginertia="1.95846e-05 1.92561e-05 5.02091e-06" />
                                                <joint name="left_r_finger_joint" pos="0 0 0" axis="0 0 1" />
                                                <geom type="mesh" rgba="0.792157 0.819608 0.933333 1" mesh="finger_limb_link" />
                                                <body name="left_r_finger_tip_link" pos="0 0.06 0" quat="0.222329 0.222329 -0.671246 -0.671244">
                                                    <inertial pos="0.000428096 -6.39629e-08 0.016281" quat="0.982245 -0.000139751 0.187603 -0.000716219" mass="0.00964245" diaginertia="1.96342e-06 1.95368e-06 4.76554e-07" />
                                                    <joint name="left_r_finger_tip_joint" pos="0 0 0" axis="0 1 0" />
                                                    <geom type="mesh" rgba="0.792157 0.819608 0.933333 1" mesh="finger_tip_link" />
                                                </body>
                                            </body>
                                            <body name="left_l_finger_link" pos="0 -0.030703 -0.071979" quat="0.31743 -0.631852 0.317435 -0.631852">
                                                <inertial pos="0.000467332 0.0122666 1.16453e-07" quat="0.705809 0.705807 -0.042877 -0.0427953" mass="0.0384621" diaginertia="1.95846e-05 1.92561e-05 5.02091e-06" />
                                                <joint name="left_l_finger_joint" pos="0 0 0" axis="0 0 1" />
                                                <geom type="mesh" rgba="0.792157 0.819608 0.933333 1" mesh="finger_limb_link" />
                                                <body name="left_l_finger_tip_link" pos="0 0.06 0" quat="0.222329 0.222329 -0.671246 -0.671244">
                                                    <inertial pos="0.000428096 -6.39629e-08 0.016281" quat="0.982245 -0.000139751 0.187603 -0.000716219" mass="0.00964245" diaginertia="1.96342e-06 1.95368e-06 4.76554e-07" />
                                                    <joint name="left_l_finger_tip_joint" pos="0 0 0" axis="0 1 0" />
                                                    <geom type="mesh" rgba="0.792157 0.819608 0.933333 1" mesh="finger_tip_link" />
                                                </body>
                                            </body>
                                            <body name="left_gripper_finger_link" pos="0 0 -0.18" quat="0.707107 -1.29867e-06 0.707107 -1.29867e-06">
                                                <inertial pos="0 0 -0.18" quat="0.707107 -1.29867e-06 0.707107 -1.29867e-06" mass="0" diaginertia="0 0 0" />
                                            </body>
                                        </body>
                                    </body>
                                    <body name="left_wrist_accel_link" pos="-0.0200083 -0.00051 -0.111067" quat="0.69759 0.69759 0.115618 -0.115618">
                                        <inertial pos="-0.0200083 -0.00051 -0.111067" quat="0.69759 0.69759 0.115618 -0.115618" mass="0" diaginertia="0 0 0" />
                                    </body>
                                </body>
                            </body>
                            <body name="left_elbow_accel_link" pos="-0.0200083 -0.00051 -0.111067" quat="0.69759 0.69759 0.115618 -0.115618">
                                <inertial pos="-0.0200083 -0.00051 -0.111067" quat="0.69759 0.69759 0.115618 -0.115618" mass="0" diaginertia="0 0 0" />
                            </body>
                        </body>
                    </body>
                    <body name="left_shoulder_accel_link" pos="-0.0200083 -0.00051 -0.111067" quat="0.69759 0.69759 0.115618 -0.115618">
                        <inertial pos="-0.0200083 -0.00051 -0.111067" quat="0.69759 0.69759 0.115618 -0.115618" mass="0" diaginertia="0 0 0" />
                    </body>
                </body>
            </body>
            <body name="right_base_link" pos="-0.01409 -0.11289 0" quat="0.0778258 0.246842 -0.290461 0.921219">
                <inertial pos="0.0560024 0.000189446 0.0201836" quat="-0.000530006 0.707989 0.00204572 0.70622" mass="0.284612" diaginertia="0.00239707 0.00197713 0.000716923" />
                <geom type="mesh" rgba="0.792157 0.819608 0.933333 1" mesh="arm_base_link_v1" />
                <body name="right_shoulder_roll_link" pos="0 0 0.087371" quat="-3.67321e-06 1 0 0">
                    <inertial pos="0.00526386 2.70692e-05 -0.0641638" quat="0.999876 0.0133095 -0.00835638 -0.000644765" mass="1.88492" diaginertia="0.00615005 0.00509851 0.00418291" />
                    <joint name="right_base_roll_joint" pos="0 0 0" axis="0 0 1" limited="true" range="-3.3999 2.3412" />
                    <geom type="mesh" rgba="1 1 1 1" mesh="roll_link_v1" />
                    <body name="right_shoulder_lift_link" pos="-0.01143 0 -0.18056" quat="-2.59734e-06 2.59735e-06 -0.707108 0.707105">
                        <inertial pos="-5.00836e-06 0.000232928 -1.77451e-05" mass="0.58967" diaginertia="0.00116314 0.000985221 0.000891661" />
                        <joint name="right_shoulder_lift_joint" pos="0 0 0" axis="0 0 1" limited="true" range="-2.2944 0" />
                        <geom type="mesh" rgba="0.116747 0.862745 1 1" mesh="lift_link_v1" />
                        <body name="right_elbow_roll_link" pos="0 0.070147 -6.25e-05" quat="-0.499128 -0.499122 0.500876 -0.500871">
                            <inertial pos="0.00526386 2.70692e-05 -0.0641638" quat="0.999876 0.0133095 -0.00835638 -0.000644765" mass="1.88492" diaginertia="0.00615005 0.00509851 0.00418291" />
                            <joint name="right_shoulder_roll_joint" pos="0 0 0" axis="0 0 1" limited="true" range="-2.6761 2.6761" />
                            <geom type="mesh" rgba="1 1 1 1" mesh="roll_link_v1" />
                            <body name="right_elbow_lift_link" pos="-0.01143 0 -0.18056" quat="-2.59734e-06 2.59735e-06 -0.707108 0.707105">
                                <inertial pos="-5.00836e-06 0.000232928 -1.77451e-05" mass="0.58967" diaginertia="0.00116314 0.000985221 0.000891661" />
                                <joint name="right_elbow_lift_joint" pos="0 0 0" axis="0 0 1" limited="true" range="-2.2944 0" />
                                <geom type="mesh" rgba="0.116747 0.862745 1 1" mesh="lift_link_v1" />
                                <body name="right_wrist_roll_link" pos="0 0.070147 -6.25e-05" quat="0.499124 0.499126 0.500872 -0.500874">
                                    <inertial pos="0.00526386 2.70692e-05 -0.0641638" quat="0.999876 0.0133095 -0.00835638 -0.000644765" mass="1.6251" diaginertia="0.00615005 0.00509851 0.00418291" />
                                    <joint name="right_elbow_roll_joint" pos="0 0 0" axis="0 0 1" limited="true" range="-2.6761 2.6761" />
                                    <geom type="mesh" rgba="1 1 1 1" mesh="roll_link_v1" />
                                    <body name="right_wrist_lift_link" pos="-0.01143 0 -0.18056" quat="-2.59734e-06 2.59735e-06 -0.707108 0.707105">
                                        <inertial pos="-5.00836e-06 0.000232928 -1.77451e-05" mass="0.44906" diaginertia="0.00116314 0.000985221 0.000891661" />
                                        <joint name="right_wrist_lift_joint" pos="0 0 0" axis="0 0 1" limited="true" range="-2.2944 0" />
                                        <geom type="mesh" rgba="0.116747 0.862745 1 1" mesh="lift_link_v1" />
                                        <body name="right_end_roll_link" pos="0 0.070147 -6.25e-05" quat="-2.59734e-06 2.59735e-06 0.707108 -0.707105">
                                            <inertial pos="0.00526386 2.70692e-05 -0.0641638" quat="0.99991 0.000246685 0.0133803 0.00035395" mass="0.65711" diaginertia="0.00578835 0.00530224 0.0034223" />
                                            <joint name="right_wrist_roll_joint" pos="0 0 0" axis="0 0 1" limited="true" range="-2.6761 2.6761" />
                                            <geom type="mesh" rgba="1 1 1 1" mesh="hand_base_link" />
                                            <body name="right_gripper_link" pos="0 0 -0.1" quat="0.535369 0.498747 0.498747 -0.464631">
                                                <inertial pos="-7.00549e-05 2.51272e-05 -0.0523671" quat="1 5.54202e-05 -0.000544908 -0.000762021" mass="0.00471098" diaginertia="0.000916889 0.000877269 0.000293332" />
                                                <joint name="right_gripper_joint" pos="0 0 0" axis="0 0 1" limited="true" range="0 1.05" />
                                            </body>
                                            <body name="right_r_finger_link" pos="0 0.030703 -0.071979" quat="0.631851 -0.317432 -0.631853 0.317432">
                                                <inertial pos="0.000467332 0.0122666 1.16453e-07" quat="0.705809 0.705807 -0.042877 -0.0427953" mass="0.0384621" diaginertia="1.95846e-05 1.92561e-05 5.02091e-06" />
                                                <joint name="right_r_finger_joint" pos="0 0 0" axis="0 0 1" />
                                                <geom type="mesh" rgba="0.792157 0.819608 0.933333 1" mesh="finger_limb_link" />
                                                <body name="right_r_finger_tip_link" pos="0 0.06 0" quat="0.222329 0.222329 -0.671246 -0.671244">
                                                    <inertial pos="0.000428096 -6.39629e-08 0.016281" quat="0.982245 -0.000139751 0.187603 -0.000716219" mass="0.00964245" diaginertia="1.96342e-06 1.95368e-06 4.76554e-07" />
                                                    <joint name="right_r_finger_tip_joint" pos="0 0 0" axis="0 1 0" />
                                                    <geom type="mesh" rgba="0.792157 0.819608 0.933333 1" mesh="finger_tip_link" />
                                                </body>
                                            </body>
                                            <body name="right_l_finger_link" pos="0 -0.030703 -0.071979" quat="0.31743 -0.631852 0.317435 -0.631852">
                                                <inertial pos="0.000467332 0.0122666 1.16453e-07" quat="0.705809 0.705807 -0.042877 -0.0427953" mass="0.0384621" diaginertia="1.95846e-05 1.92561e-05 5.02091e-06" />
                                                <joint name="right_l_finger_joint" pos="0 0 0" axis="0 0 1" />
                                                <geom type="mesh" rgba="0.792157 0.819608 0.933333 1" mesh="finger_limb_link" />
                                                <body name="right_l_finger_tip_link" pos="0 0.06 0" quat="0.222329 0.222329 -0.671246 -0.671244">
                                                    <inertial pos="0.000428096 -6.39629e-08 0.016281" quat="0.982245 -0.000139751 0.187603 -0.000716219" mass="0.00964245" diaginertia="1.96342e-06 1.95368e-06 4.76554e-07" />
                                                    <joint name="right_l_finger_tip_joint" pos="0 0 0" axis="0 1 0" />
                                                    <geom type="mesh" rgba="0.792157 0.819608 0.933333 1" mesh="finger_tip_link" />
                                                </body>
                                            </body>
                                            <body name="right_gripper_finger_link" pos="0 0 -0.18" quat="0.707107 -1.29867e-06 0.707107 -1.29867e-06">
                                                <inertial pos="0 0 -0.18" quat="0.707107 -1.29867e-06 0.707107 -1.29867e-06" mass="0" diaginertia="0 0 0" />
                                            </body>
                                        </body>
                                    </body>
                                    <body name="right_wrist_accel_link" pos="-0.0200083 -0.00051 -0.111067" quat="0.69759 0.69759 0.115618 -0.115618">
                                        <inertial pos="-0.0200083 -0.00051 -0.111067" quat="0.69759 0.69759 0.115618 -0.115618" mass="0" diaginertia="0 0 0" />
                                    </body>
                                </body>
                            </body>
                            <body name="right_elbow_accel_link" pos="-0.0200083 -0.00051 -0.111067" quat="0.69759 0.69759 0.115618 -0.115618">
                                <inertial pos="-0.0200083 -0.00051 -0.111067" quat="0.69759 0.69759 0.115618 -0.115618" mass="0" diaginertia="0 0 0" />
                            </body>
                        </body>
                    </body>
                    <body name="right_shoulder_accel_link" pos="-0.0200083 -0.00051 -0.111067" quat="0.69759 0.69759 0.115618 -0.115618">
                        <inertial pos="-0.0200083 -0.00051 -0.111067" quat="0.69759 0.69759 0.115618 -0.115618" mass="0" diaginertia="0 0 0" />
                    </body>
                </body>
            </body>
            <body name="camera_link" pos="-0.01905 0 0.303507" quat="0.707107 0.707107 0 0">
                <inertial pos="-0.00759217 0.0650724 0.000615586" quat="0.999769 -0.000313494 0.000866284 -0.0214595" mass="0.274759" diaginertia="0.000597521 0.000569066 0.000184847" />
                <geom type="mesh" rgba="0.792157 0.819608 0.933333 1" mesh="camera_link" />
                <body name="camera_view_link" pos="0.01905 0.072775 0" quat="0.707107 0 -0.707107 0">
                    <inertial pos="0.01905 0.072775 0" quat="0.707107 0 -0.707107 0" mass="0" diaginertia="0 0 0" />
                </body>
            </body>
        </body>
    </worldbody>
</mujoco>
