<!-- ======================================================
	This file is part of MuJoCo.
	Copyright 2009-2016 Roboti LLC.

	Model 		:: PR2 from Willow Garage
		Source		: (Provided by Sergey Levine, UC Berkeley)
		Downloaded	: 18July'14

	Mujoco		:: Advanced physics simulation engine
		Source		: www.roboti.us
		Version		: 1.31
		Released 	: 23Apr16

	Author		:: Vikash Kumar
		Contacts 	: kumar@roboti.us
		Last edits 	: 30Apr'16, 14Dec'15, 10Oct'15
====================================================== -->

<mujoco model="pr2(v1.31)">
    <compiler 	meshdir="Meshes/"
				coordinate="local"
				angle="radian"/>

	<option timestep="0.01"
			gravity="0 0 0"/>

	<asset>
		<mesh file="base_L.stl"/>
		<mesh file="caster_L.stl"/>
		<mesh file="torso_lift_L.stl"/>
		<mesh file="head_pan_L.stl"/>
		<mesh file="head_tilt_L.stl"/>
		<mesh file="tilting_hokuyo_L.stl"/>
		<mesh file="shoulder_pan.stl"/>
		<mesh file="shoulder_lift.stl"/>
		<mesh file="upper_arm_roll_L.stl"/>
		<mesh file="upper_arm.stl"/>
		<mesh file="elbow_flex.stl"/>
		<mesh file="forearm_roll_L.stl"/>
		<mesh file="forearm.stl"/>


		<mesh file="wrist_flex.stl"/>
		<mesh file="wrist_roll_L.stl"/>
		<mesh file="gripper_palm.stl"/>
		<mesh file="l_finger.stl"/>
		<mesh file="l_finger_tip.stl"/>

        <mesh name="base_plate" file="./peg_task/base_plate.stl" scale="0.02 0.02 0.02"/>
        <mesh name="compound_gear" file="./peg_task/compound_gear.stl" scale="0.03 0.03 0.03"/>
        <mesh name="gear1" file="./peg_task/gear1.stl"/>
        <mesh name="gear2" file="./peg_task/gear2.stl"/>
        <mesh name="gear2_1" file="./peg_task/gear2_1.stl"/>
        <mesh name="shaft1" file="./peg_task/shaft1.stl" scale="0.03 0.03 0.03"/>
        <mesh name="shaft2" file="./peg_task/shaft2.stl" scale="0.02 0.02 0.02"/>

		<material name="MatGnd" specular=".3" shininess=".3" reflectance="0.3" rgba=".5 .55 .5 1"/>
	</asset>


    <contact>
        <pair geom1="r_gripper_l_finger_tip" geom2="r_gripper_r_finger_tip"/>
		<pair geom1="l_gripper_l_finger_tip" geom2="l_gripper_r_finger_tip"/>
		<pair geom1="base" geom2="r_forearm"/>
		<pair geom1="base" geom2="l_forearm"/>

    </contact>

    <default>
        <joint limited="false" damping=".01" armature=".005"/>
        <geom contype="1" conaffinity="0" friction="1 0.1 0.1" type="mesh"/>
		<default class="gripper">
			<joint damping="0.005" armature=".005"/>
		</default>
    </default>

    <worldbody>
	<light directional="true" cutoff="4" exponent="20" diffuse="1 1 1" specular="0 0 0" pos=".5 0.75 1.5" dir="-.5 -0.75 -1.5"/>
	<geom name="gnd" material="MatGnd" type="plane" contype="0" conaffinity="1" pos="0 0 0" size="1.5 1.5 0.25"/>

        <body name="base_footprint" pos="0 0 0">
            <inertial pos="0 0 0" mass="1" diaginertia="0.01 0.01 0.01" />
            <!--<geom name="geom0" type="box" pos="0 0 0.071" size="0.005 0.005 0.005" rgba="1 0 0 1" group="2" />-->
            <body name="base_link" pos="0 0 0.051">
                <inertial pos="-0.061 0 0.293" quat="0.973598 0.001764 -0.228065 -0.009443" mass="116" diaginertia="6.293885 5.669245 3.041772" />
                <geom name="base" rgba="1 1 1 1" mesh="base_L" contype="0"/>
                <body name="torso_lift_link" pos="-0.05 0 1.049675">
                    <!--joint name="torso_lift_joint" type="slide" pos="0 0 0" axis="0 0 1" limited="true" range="0 0.31"/-->
                    <inertial pos="-0.1 0 -0.0885" quat="0.999335 0.007626 0.035453 0.003712" mass="36.248046" diaginertia="2.783075 2.510450 0.514581" />
                    <geom name="geom15" rgba="0.9 0.9 0.9 1" mesh="torso_lift_L" contype="0"/>
                    <geom name="laser" rgba="0.9 0.9 0.9 1" pos="0.1 0 0.225" mesh="tilting_hokuyo_L" contype="0"/>
                    <geom name="pan" rgba="0.9 0.9 0.9 1" pos="0 0 0.375" mesh="head_pan_L" contype="0"/>
                    <body name="head_tilt">
                        <geom name="tilt" rgba="0.9 0.9 0.9 1" pos="0.075 0 0.375" mesh="head_tilt_L" contype="0"/>
                        <camera pos="0.125 0.025 0.5" fovy="65" euler="0  -0.785 1.5707" name="stereo"/>
                    </body>
                    <body name="r_shoulder_pan_link" pos="0 -0.188 0">
                        <inertial pos="-0.001201 0.024513 -0.098231" quat="0.927482 -0.087656 0.074060 -0.355821" mass="25.799322" diaginertia="0.934201 0.837701 0.242033" />
                        <geom name="geom32" rgba="0 0 0.8 1" mesh="shoulder_pan" contype="0"/>
                        <body name="r_shoulder_lift_link" pos="0.1 0 0">
                            <inertial pos="0.02195 -0.02664 -0.03127" quat="0.791779 0.478014 0.238985 0.295762" mass="2.74988" diaginertia="0.026187 0.020730 0.015168" />
                            <geom name="geom33" rgba="0.7 0.7 0.7 1" mesh="shoulder_lift" contype="0"/>
                            <!--<geom name="geom33f" type="capsule" pos="0.00043735 0.00010360 0.00012870" quat="0.70990818 0.03949992 0.03636729 0.70224465" size="0.14761245 0.01591613" rgba="0.7 0.7 0.7 1" group="1"/>-->
                            <body name="r_upper_arm_roll_link" pos="0 0 0">
                                <inertial pos="0 0 0" mass="0.1" diaginertia="0.01 0.01 0.01" />
                                <!--mesh name="geom34" mesh="upper_arm_roll_L" contype="0"/-->
                                <!--geom name="geom34f" type="capsule" pos="0.12961979 -0.00000014 0" quat="1 -0.00001340 0.00000169 -0.00000728" size="0.07297432 0.00139096" group="1"/-->
                                <body name="r_upper_arm_link" pos="0 0 0">
                                    <inertial pos="0.21398 -0.01621 -0.0002" quat="-0.045020 0.697462 -0.088537 0.709705" mass="6.01769" diaginertia="0.076138 0.074931 0.015133" />
                                    <geom name="geom35" rgba="0 0.8 0 1" mesh="upper_arm" contype="0"/>
                                    <!--geom name="geom35f" type="capsule" pos="0.21533518 0.00017574 -0.00229182" quat="0.50005025 0.49945472 0.50003903 0.50045548" size="0.09823026 0.18895381" rgba="0 0.8 0 1" group="1"/-->
                                    <body name="r_elbow_flex_link" pos="0.4 0 0">
                                        <inertial pos="0.01014 0.00032 -0.01211" quat="0.308784 0.646797 0.639077 0.279083" mass="1.90327" diaginertia="0.004419 0.003965 0.003090" />
                                        <geom name="geom36" rgba="0.7 0.7 0.7 1" mesh="elbow_flex" contype="0"/>
                                        <!--geom name="geom36f" type="capsule" pos="0.01080148 -0.00019654 -0.00157206" quat="0.46319936 0.53428385 0.53426711 0.46319087" size="0.08174065 0.03329964" rgba="0.7 0.7 0.7 1" group="1"/-->
                                        <body name="r_forearm_roll_link" pos="0 0 0">
                                            <inertial pos="0 0 0" mass="0.1" diaginertia="0.01 0.01 0.01" />
                                            <!--mesh name="geom37" mesh="forearm_roll_L" contype="0"/-->
                                            <!--geom name="geom37f" type="capsule" pos="0.04279423 -0.00004959 -0.00435061" quat="-0.00043052 0.67588833 -0.00028777 0.73700387" size="0.04187753 0.05695059" group="1"/-->
                                            <body name="r_forearm_link" pos="0 0 0">
                                                <inertial pos="0.18791 -0.00017 -0.00912" quat="-0.000587 0.726286 -0.003969 0.687381" mass="2.57968" diaginertia="0.016633 0.015078 0.003609" />
                                                <geom name="r_forearm" rgba="0.7 0.7 0.7 1" mesh="forearm" contype="0"/>
                                                <!--geom name="geom38f" type="capsule" pos="0.22414201 -0.00002379 -0.00172978" quat="0.00011562 0.73364272 -0.00009110 0.67953538" size="0.06893772 0.10796238" rgba="0.7 0.7 0.7 1" group="1"/-->
                                                <!--geom name="geom38f" type="box" pos="0.22414201 -0.00002379 -0.00172978" size="0.13 0.06 0.05" rgba="0.7 0.7 0.7 1" group="1"/-->
                                               <body name="r_wrist_flex_link" pos="0.321 0 0">
                                                    <inertial pos="-0.00157 0 -0.00075" quat="0.695976 0.696411 -0.123560 0.123942" mass="0.61402" diaginertia="0.000653 0.000643 0.000198" />
                                                    <geom name="geom39" rgba="0.7 0.7 0.7 1" mesh="wrist_flex" contype="0"/>
                                                    <!--geom name="geom39f" type="capsule" pos="-0.00166503 -0.00000018 -0.00367085" quat="0.70247354 -0.08138660 -0.08143754 0.70233544" size="0.03978695 0.01715654" rgba="0.7 0.7 0.7 1" group="1"/-->
                                                    <body name="r_wrist_roll_link" pos="0 0 0">
                                                        <inertial pos="0 0 0" mass="0.1" diaginertia="0.01 0.01 0.01" />
                                                        <!--mesh name="geom40" mesh="wrist_roll_L" contype="0"/-->
                                                        <!--geom name="geom40f" type="capsule" pos="0.03324894 0.00005320 -0.00012423" quat="0.67531716 0.73752742 -0.00019246 0.00000483" size="0.02078140 0.00071779" group="1"/-->
                                                        <body name="r_gripper_palm_link" pos="0 0 0" childclass="gripper">
                                                            <inertial pos="0.06623 0.00053 -0.00119" quat="-0.018184 0.706274 0.016077 0.707523" mass="0.58007" diaginertia="0.000866 0.000678 0.000351" />
                                                            <geom name="geom41" rgba="0.8 0 0 1" mesh="gripper_palm" contype="0"/>
                                                            <geom name="geom41f" type="capsule" pos="0.07750326 0.00000579 -0.00000142" quat="0.49981788 0.50015276 -0.49991269 0.50011660" size="0.05263874 0.00669171" rgba="0.8 0 0 1" group="1"/>
                                                            <body name="r_gripper_l_finger_link" pos="0.07691 0.01 0">
                                                                <inertial pos="0.03598 0.0173 -0.00164" quat="0.574440 0.429111 0.518782 0.465562" mass="0.17126" diaginertia="0.000198 0.000181 0.000077" />
                                                                <geom name="geom43" rgba="0.7 0.7 0.7 1" mesh="l_finger" />
                                                                <body name="r_gripper_l_finger_tip_link" pos="0.09137 0.00495 0">
                                                                    <inertial pos="0.00423 0.00284 0" quat="0.249588 0.661594 -0.249588 0.661594" mass="0.04419" diaginertia="0.000015 0.000015 0.000003" />                                                                    <geom name="r_gripper_l_finger_tip" rgba="0 0.8 0 1" mesh="l_finger_tip" />
                                                                </body>
                                                            </body>
                                                            <body name="r_gripper_r_finger_link" pos="0.07691 -0.01 0">
                                                                <inertial pos="0.03576 -0.01736 -0.00095" quat="0.474684 0.510909 0.446353 0.560727" mass="0.17389" diaginertia="0.000199 0.000181 0.000077" />
                                                                <geom name="geom45" rgba="0.7 0.7 0.7 1" euler="3.14 0 0" mesh="l_finger" />
                                                                <body name="r_gripper_r_finger_tip_link" pos="0.09137 -0.00495 0">
                                                                    <inertial pos="0.00423 -0.00284 0" quat="-0.249588 0.661594 0.249588 0.661594" mass="0.04419" diaginertia="0.000015 0.000015 0.000003" />
                                                                    <geom name="r_gripper_r_finger_tip" euler="3.14 0 0" rgba="0 0.8 0 1" mesh="l_finger_tip" />
                                                                </body>
                                                            </body>
                                                        </body>
                                                    </body>
                                                </body>
                                            </body>
                                        </body>
                                    </body>
                                </body>
                            </body>
                        </body>
                    </body>
                    <body name="l_shoulder_pan_link" pos="0 0.188 0">
                        <inertial pos="-0.001201 0.024513 -0.098231" quat="0.927482 -0.087656 0.074060 -0.355821" mass="25.799322" diaginertia="0.934201 0.837701 0.242033" />
                        <joint name="l_shoulder_pan_joint" type="hinge" pos="0 0 0" axis="0 0 1" limited="true" range="-0.714602 2.285398"/>
                        <geom name="geom50" rgba="0 0 0.8 1" mesh="shoulder_pan" contype="0"/>
                        <body name="l_shoulder_lift_link" pos="0.1 0 0">
                            <inertial pos="0.02195 -0.02664 -0.03127" quat="0.791779 0.478014 0.238985 0.295762" mass="2.74988" diaginertia="0.026187 0.020730 0.015168" />
                            <joint name="l_shoulder_lift_joint" type="hinge" pos="0 0 0" axis="0 1 0" limited="true" range="-0.5236 1.3963"/>
                            <geom name="geom51" rgba="0.7 0.7 0.7 1" mesh="shoulder_lift" />
                            <body name="l_upper_arm_roll_link" pos="0 0 0">
                                <inertial pos="0 0 0" mass="0.1" diaginertia="0.01 0.01 0.01" />
                                <joint name="l_upper_arm_roll_joint" type="hinge" pos="0 0 0" axis="1 0 0" limited="true" range="-0.8 3.9"/>
                                <body name="l_upper_arm_link" pos="0 0 0">
                                    <inertial pos="0.21405 0.01658 -0.00057" quat="-0.090901 0.708675 -0.051638 0.697746" mass="6.01769" diaginertia="0.076070 0.074882 0.015107" />
                                    <geom name="geom53" rgba="0 0.8 0 1" mesh="upper_arm" contype="0"/>
                                    <body name="l_elbow_flex_link" pos="0.4 0 0">
                                        <inertial pos="0.01014 0.00032 -0.01211" quat="0.308784 0.646797 0.639077 0.279083" mass="1.90327" diaginertia="0.004419 0.003965 0.003090" />
                                        <joint name="l_elbow_flex_joint" type="hinge" pos="0 0 0" axis="0 1 0" limited="true" range="-2.3213 0"/>
                                        <geom name="geom54" rgba="0.7 0.7 0.7 1" mesh="elbow_flex" />
                                        <body name="l_forearm_roll_link" pos="0 0 0">
                                            <inertial pos="0 0 0" mass="0.1" diaginertia="0.01 0.01 0.01" />
                                            <joint name="l_forearm_roll_joint" type="hinge"   pos="0 0 0" axis="1 0 0"/>
                                            <body name="l_forearm_link" pos="0 0 0">
                                                <inertial pos="0.18791 -0.00017 -0.00912" quat="-0.000587 0.726286 -0.003969 0.687381" mass="2.57968" diaginertia="0.016633 0.015078 0.003609" />
                                                <geom name="l_forearm" rgba="0.7 0.7 0.7 1" mesh="forearm" contype="0"/>
                                                <body name="l_wrist_flex_link" pos="0.321 0 0">
                                                    <inertial pos="-0.00157 0 -0.00075" quat="0.695976 0.696411 -0.123560 0.123942" mass="0.61402" diaginertia="0.000653 0.000643 0.000198" />
                                                    <joint name="l_wrist_flex_joint" type="hinge" pos="0 0 0" axis="0 1 0" limited="true" range="-2.094 0"/>
                                                    <geom name="geom57" rgba="0.7 0.7 0.7 1" mesh="wrist_flex"/>
                                                    <body name="l_wrist_roll_link" pos="0 0 0">
                                                        <inertial pos="0 0 0" mass="0.1" diaginertia="0.01 0.01 0.01" />
                                                        <joint name="l_wrist_roll_joint" type="hinge"   pos="0 0 0" axis="1 0 0"/>
                                                        <body name="l_gripper_palm_link" pos="0 0 0" childclass="gripper">
                                                            <inertial pos="0.06623 0.00053 -0.00119" quat="-0.018184 0.706274 0.016077 0.707523" mass="0.58007" diaginertia="0.000866 0.000678 0.000351" />
                                                            <geom name="geom59" rgba="0.8 0 0 1" mesh="gripper_palm" contype="0"/>
                                                            <body name="sensor" pos="0.01 0 0">
                                                                <geom name="sensor" rgba="0.7 0.7 0.7 1" type="cylinder" size="0.022 0.019" pos="0 0 0" quat="-0.018184 0.706274 0.016077 0.707523"/>
                                                            </body>
                                                            <body name="l_gripper_led_frame" pos="0.0513 0 0.0244">
                                                                <inertial pos="0 0 0" mass="0.001" diaginertia="0.000000 0.000000 0.000000" />
                                                            </body>
                                                            <body name="l_gripper_motor_accelerometer_link" pos="0 0 0">
                                                                <inertial pos="0 0 0" mass="0.001" diaginertia="0.001 0.001 0.001" />
                                                                <!--geom name="geom60" type="box" pos="0 0 0" size="0.0005 0.0005 0.0005" /-->
                                                            </body>
                                                                <body name="l_gripper_tool_frame" pos="0.18 0 0">
                                                            </body>
                                                            <!--geom name="geom59f" type="capsule" pos="0.07750326 -0.00000579 -0.00000142" quat="0.49981788 0.50015276 -0.49991269 0.50011660" size="0.05263874 0.00669171" rgba="0.8 0 0 1" group="1"/-->
                                                            <body name="l_gripper_l_finger_link" pos="0.07691 0.01 0">
                                                                <inertial pos="0.03598 0.0173 -0.00164" quat="0.574440 0.429111 0.518782 0.465562" mass="0.17126" diaginertia="0.000198 0.000181 0.000077" />
                                                                <geom name="geom61" rgba="0.7 0.7 0.7 1" mesh="l_finger" />
                                                                <body name="l_gripper_l_finger_tip_link" pos="0.09137 0.00495 0">
                                                                    <inertial pos="0.00423 0.00284 0" quat="0.249588 0.661594 -0.249588 0.661594" mass="0.04419" diaginertia="0.000015 0.000015 0.000003" />
                                                                    <geom name="l_gripper_l_finger_tip" rgba="0 0.8 0 1" mesh="l_finger_tip" />
                                                                </body>
                                                            </body>
                                                            <body name="l_gripper_r_finger_link" pos="0.07691 -0.01 0">
                                                                <inertial pos="0.03576 -0.01736 -0.00095" quat="0.474684 0.510909 0.446353 0.560727" mass="0.17389" diaginertia="0.000199 0.000181 0.000077" />
                                                                <geom name="geom63" euler="3.14 0 0" rgba="0.7 0.7 0.7 1" mesh="l_finger" />
                                                                <body name="l_gripper_r_finger_tip_link" pos="0.09137 -0.00495 0">
                                                                    <inertial pos="0.00423 -0.00284 0" quat="-0.249588 0.661594 0.249588 0.661594" mass="0.04419" diaginertia="0.000015 0.000015 0.000003" />
                                                                    <geom name="l_gripper_r_finger_tip" euler="3.14 0 0" rgba="0 0.8 0 1" mesh="l_finger_tip" />
                                                                    <body name="ee_pos" pos="0.03275 0.0154 -0.003275">
                                                                        <geom type="mesh" mesh="shaft2" rgba="0 1 0 1" pos="-0.04 0 0" quat="0.7071 0 0.7071 0" conaffinity="1" contype="1"/>
                                                                    </body>
                                                                </body>
                                                            </body>
                                                        </body>
                                                    </body>
                                                </body>
                                            </body>
                                        </body>
                                    </body>
                                </body>
                            </body>
                        </body>
                    </body>
                </body>
            </body>
        </body>
        <body name="peg_asset" pos="0 0 0">
            <geom type="mesh" rgba="1 0 0 1" mesh="base_plate" conaffinity="1" contype="1"/>
            <geom type="box"  rgba="1 0 0 1" conaffinity="1" contype="1" size="0.5 0.5 0.001"/>

            <body name="g1" pos="0 0 0">
                <geom name="g1" type="sphere" rgba="0.0 1.0 0.0 1.0" pos="0 0 0" size="0.01"/>
            </body>

            <body name="g2" pos="0.0 0.3 -0.7">
                <geom name="goal-top" type="sphere" rgba="1.0 0.0 0.0 1" pos="0.0 0.0 0.0" size="0.00000001" />
            </body>

            <body name="g3" pos="0 0.3 -0.7">
                <geom name="goal-bottom" type="sphere" rgba="0.0 0.0 1.0 1" pos="0.0 0.0 0.0" size="0.01" />
            </body>
        </body>
    </worldbody>
    <actuator>
        <motor joint="l_shoulder_pan_joint" ctrlrange="-3.0 3.0" ctrllimited="false"/>
        <motor joint="l_shoulder_lift_joint" ctrlrange="-3.0 3.0" ctrllimited="false"/>
        <motor joint="l_upper_arm_roll_joint" ctrlrange="-3.0 3.0" ctrllimited="false"/>
        <motor joint="l_elbow_flex_joint" ctrlrange="-3.0 3.0" ctrllimited="false"/>
        <motor joint="l_forearm_roll_joint" ctrlrange="-3.0 3.0" ctrllimited="false"/>
        <motor joint="l_wrist_flex_joint" ctrlrange="-3.0 3.0" ctrllimited="false"/>
        <motor joint="l_wrist_roll_joint" ctrlrange="-3.0 3.0" ctrllimited="false"/>
    </actuator>
</mujoco>
