<mujoco>
  <compiler inertiafromgeom="true" angle="degree" coordinate="local" />
  <option timestep="0.1" integrator="RK4" />
  <default>
    <joint limited="false" armature="0" damping="0" />
    <geom condim="3" conaffinity="0" margin="0" friction="1 0.5 0.5" rgba="0.8 0.6 0.4 1" density="100" />
  </default>
  <asset>
    <texture type="skybox" builtin="gradient" width="100" height="100" rgb1="1 1 1" rgb2="0 0 0" />
    <texture name="texgeom" type="cube" builtin="flat" mark="cross" width="127" height="1278" rgb1="0.8 0.6 0.4" rgb2="0.8 0.6 0.4" markrgb="1 1 1" random="0.01" />
    <texture name="texplane" type="2d" builtin="checker" rgb1="0 0 0" rgb2="0.8 0.8 0.8" width="100" height="100" />
    <material name='MatPlane' texture="texplane" shininess="1" texrepeat="30 30" specular="1"  reflectance="0.5" />
    <material name='geom' texture="texgeom" texuniform="true" />
    <material name="MatGnd" specular="0" shininess="0" reflectance="0" rgba='1 1 1 1'/>
  </asset>
  <worldbody>
    <camera name="main" pos="0 0 5" euler="0 0 0" fovy="65" />
    <light directional="true" cutoff="100" exponent="1" diffuse="1 1 1" specular=".1 .1 .1" pos="0 0 1.3" dir="-0 0 -1.3" />
    <!--geom name="gnd" material="MatGnd" type="plane" contype="0" conaffinity="0" pos="0 0 0" size="40 40 40"/-->
    <geom name='floor' material="MatPlane" pos='0 0 0' size='40 40 40' type='plane' conaffinity='1' rgba='0.8 0.9 0.8 1' condim='3' />
    <body name="torso" pos="0 0 0">
      <geom name="pointbody" type="sphere" size="0.2" pos="0 0 0.2" />
      <joint name='ballx' type='slide' axis='1 0 0' pos='0 0 0' damping="15"/>
      <joint name='bally' type='slide' axis='0 1 0' pos='0 0 0' damping="15"/>
    </body>
    <body name="dis1" pos="0 0 0">
      <geom name="dis1_geom" type="box" size="0.4 0.4 0.4" pos="0 0 0.4" rgba="0 1 0 1"/>
      <joint name='dis1x' type='slide' axis='1 0 0' pos='0 0 0' damping="15"/>
      <joint name='dis1y' type='slide' axis='0 1 0' pos='0 0 0' damping="15"/>
    </body>
    <body name="dis2" pos="0 0 0">
      <geom name="dis2_geom" type="sphere" size="0.5" pos="0 0 0.5" rgba="1 0 0 1" />
      <joint name='dis2x' type='slide' axis='1 0 0' pos='0 0 0' damping="15"/>
      <joint name='dis2y' type='slide' axis='0 1 0' pos='0 0 0' damping="15"/>
    </body>
  </worldbody>
  <actuator>
    <!-- Those are just dummy actuators for providing ranges -->
    <position joint='ballx' ctrlrange="-20 20" ctrllimited="true" kp="150"/>
    <position joint='bally' ctrlrange ="-20 20" ctrllimited="true" kp="150"/>
  </actuator>
</mujoco>